Workbook

Sheet IT Budget Summary
A1: ACA / SAMA — IT Budget Summary | FY 2026-27 | Live-Linked to Trackers | KWD
A2: ▶ MASTER SCENARIO: | C2: Offline Optimized | E2: ← one control drives every tracker. Approved 2025-26 = frozen prior-year.
A4: ▶ SECTION 1 — BY ENTITY & CATEGORY
A5: Entity / Category | C5: Approved 2025-26 | D5: Budget 2026-27 | E5: Utilized | F5: Available | G5: % Used | H5: Notes
A6: ACA Hawally — Capital | C6: ='ACAH Capital Tracker'!M30 -> 74060 | D6: ='ACAH Capital Tracker'!E30 -> 54150 | E6: ='ACAH Capital Tracker'!F30 -> 0 | F6: =D6-E6 -> 54150 | G6: =IFERROR(E6/D6,0) -> 0
A7: ACA Hawally — Consumables | C7: ='ACAH Consumables Tracker'!M44 -> 185940 | D7: ='ACAH Consumables Tracker'!E44 -> 197910 | E7: ='ACAH Consumables Tracker'!F44 -> 1776.818 | F7: =D7-E7 -> 196133.18 | G7: =IFERROR(E7/D7,0) -> 0.0089779092
A8: ACA Salmiya — Capital | C8: ='ACAS Capital Tracker'!M33 -> 68190 | D8: ='ACAS Capital Tracker'!E33 -> 55625 | E8: ='ACAS Capital Tracker'!F33 -> 0 | F8: =D8-E8 -> 55625 | G8: =IFERROR(E8/D8,0) -> 0
A9: ACA Salmiya — Consumables | C9: ='ACAS Consumables Tracker'!M42 -> 132220 | D9: ='ACAS Consumables Tracker'!E42 -> 146540 | E9: ='ACAS Consumables Tracker'!F42 -> 7361.212 | F9: =D9-E9 -> 139178.79 | G9: =IFERROR(E9/D9,0) -> 0.050233465
A10: SAMA — Capital | C10: ='SAMA Capital Tracker'!M17 -> 6100 | D10: ='SAMA Capital Tracker'!E17 -> 4750 | E10: ='SAMA Capital Tracker'!F17 -> 0 | F10: =D10-E10 -> 4750 | G10: =IFERROR(E10/D10,0) -> 0
A11: SAMA — Consumables | C11: ='SAMA Consumables Tracker'!M24 -> 38700 | D11: ='SAMA Consumables Tracker'!E24 -> 55900 | E11: ='SAMA Consumables Tracker'!F24 -> 750 | F11: =D11-E11 -> 55150 | G11: =IFERROR(E11/D11,0) -> 0.013416816
A12: GRAND TOTAL — IT BUDGET | C12: =SUM(C6:C11) -> 505210 | D12: =SUM(D6:D11) -> 514875 | E12: =SUM(E6:E11) -> 9888.03 | F12: =D12-E12 -> 504986.97 | G12: =IFERROR(E12/D12,0) -> 0.01920472
A14: ▶ SECTION 2 — BY GL CODE (all entities, current scenario)
A15: GL Code | B15: GL Description | D15: Budget 2026-27 | E15: Utilized | F15: Available | G15: % Used
A16: 1101010009 | B16: IT & Computer Equipment (Capex) | D16: =SUMIF('ACAH Capital Tracker'!$D:$D,$A16,'ACAH Capital Tracker'!$E:$E)+SUMIF('ACAH Consumables Tracker'!$D:$D,$A16,'ACAH Consumables Tracker'!$E:$E)+SUMIF('ACAS Capital Tracker'!$D:$D,$A16,'ACAS Capital Tracker'!$E:$E)+SUMIF('ACAS Consumables Tracker'!$D:$D,$A16,'ACAS Consumables Tracker'!$E:$E)+SUMIF('SAMA Capital Tracker'!$D:$D,$A16,'SAMA Capital Tracker'!$E:$E)+SUMIF('SAMA Consumables Tracker'!$D:$D,$A16,'SAMA Consumables Tracker'!$E:$E) -> 114525 | E16: =SUMIF('ACAH Capital Tracker'!$D:$D,$A16,'ACAH Capital Tracker'!$F:$F)+SUMIF('ACAH Consumables Tracker'!$D:$D,$A16,'ACAH Consumables Tracker'!$F:$F)+SUMIF('ACAS Capital Tracker'!$D:$D,$A16,'ACAS Capital Tracker'!$F:$F)+SUMIF('ACAS Consumables Tracker'!$D:$D,$A16,'ACAS Consumables Tracker'!$F:$F)+SUMIF('SAMA Capital Tracker'!$D:$D,$A16,'SAMA Capital Tracker'!$F:$F)+SUMIF('SAMA Consumables Tracker'!$D:$D,$A16,'SAMA Consumables Tracker'!$F:$F) -> 0 | F16: =D16-E16 -> 114525 | G16: =IFERROR(E16/D16,0) -> 0
A17: 5101030002 | B17: Communication / Bulk SMS Charges | D17: =SUMIF('ACAH Capital Tracker'!$D:$D,$A17,'ACAH Capital Tracker'!$E:$E)+SUMIF('ACAH Consumables Tracker'!$D:$D,$A17,'ACAH Consumables Tracker'!$E:$E)+SUMIF('ACAS Capital Tracker'!$D:$D,$A17,'ACAS Capital Tracker'!$E:$E)+SUMIF('ACAS Consumables Tracker'!$D:$D,$A17,'ACAS Consumables Tracker'!$E:$E)+SUMIF('SAMA Capital Tracker'!$D:$D,$A17,'SAMA Capital Tracker'!$E:$E)+SUMIF('SAMA Consumables Tracker'!$D:$D,$A17,'SAMA Consumables Tracker'!$E:$E) -> 14500 | E17: =SUMIF('ACAH Capital Tracker'!$D:$D,$A17,'ACAH Capital Tracker'!$F:$F)+SUMIF('ACAH Consumables Tracker'!$D:$D,$A17,'ACAH Consumables Tracker'!$F:$F)+SUMIF('ACAS Capital Tracker'!$D:$D,$A17,'ACAS Capital Tracker'!$F:$F)+SUMIF('ACAS Consumables Tracker'!$D:$D,$A17,'ACAS Consumables Tracker'!$F:$F)+SUMIF('SAMA Capital Tracker'!$D:$D,$A17,'SAMA Capital Tracker'!$F:$F)+SUMIF('SAMA Consumables Tracker'!$D:$D,$A17,'SAMA Consumables Tracker'!$F:$F) -> 0 | F17: =D17-E17 -> 14500 | G17: =IFERROR(E17/D17,0) -> 0
A18: 5101130003 | B18: Toners, Cartridges & Accessories | D18: =SUMIF('ACAH Capital Tracker'!$D:$D,$A18,'ACAH Capital Tracker'!$E:$E)+SUMIF('ACAH Consumables Tracker'!$D:$D,$A18,'ACAH Consumables Tracker'!$E:$E)+SUMIF('ACAS Capital Tracker'!$D:$D,$A18,'ACAS Capital Tracker'!$E:$E)+SUMIF('ACAS Consumables Tracker'!$D:$D,$A18,'ACAS Consumables Tracker'!$E:$E)+SUMIF('SAMA Capital Tracker'!$D:$D,$A18,'SAMA Capital Tracker'!$E:$E)+SUMIF('SAMA Consumables Tracker'!$D:$D,$A18,'SAMA Consumables Tracker'!$E:$E) -> 36750 | E18: =SUMIF('ACAH Capital Tracker'!$D:$D,$A18,'ACAH Capital Tracker'!$F:$F)+SUMIF('ACAH Consumables Tracker'!$D:$D,$A18,'ACAH Consumables Tracker'!$F:$F)+SUMIF('ACAS Capital Tracker'!$D:$D,$A18,'ACAS Capital Tracker'!$F:$F)+SUMIF('ACAS Consumables Tracker'!$D:$D,$A18,'ACAS Consumables Tracker'!$F:$F)+SUMIF('SAMA Capital Tracker'!$D:$D,$A18,'SAMA Capital Tracker'!$F:$F)+SUMIF('SAMA Consumables Tracker'!$D:$D,$A18,'SAMA Consumables Tracker'!$F:$F) -> 0 | F18: =D18-E18 -> 36750 | G18: =IFERROR(E18/D18,0) -> 0
A19: 5101160003 | B19: Computer & Server Maintenance | D19: =SUMIF('ACAH Capital Tracker'!$D:$D,$A19,'ACAH Capital Tracker'!$E:$E)+SUMIF('ACAH Consumables Tracker'!$D:$D,$A19,'ACAH Consumables Tracker'!$E:$E)+SUMIF('ACAS Capital Tracker'!$D:$D,$A19,'ACAS Capital Tracker'!$E:$E)+SUMIF('ACAS Consumables Tracker'!$D:$D,$A19,'ACAS Consumables Tracker'!$E:$E)+SUMIF('SAMA Capital Tracker'!$D:$D,$A19,'SAMA Capital Tracker'!$E:$E)+SUMIF('SAMA Consumables Tracker'!$D:$D,$A19,'SAMA Consumables Tracker'!$E:$E) -> 6750 | E19: =SUMIF('ACAH Capital Tracker'!$D:$D,$A19,'ACAH Capital Tracker'!$F:$F)+SUMIF('ACAH Consumables Tracker'!$D:$D,$A19,'ACAH Consumables Tracker'!$F:$F)+SUMIF('ACAS Capital Tracker'!$D:$D,$A19,'ACAS Capital Tracker'!$F:$F)+SUMIF('ACAS Consumables Tracker'!$D:$D,$A19,'ACAS Consumables Tracker'!$F:$F)+SUMIF('SAMA Capital Tracker'!$D:$D,$A19,'SAMA Capital Tracker'!$F:$F)+SUMIF('SAMA Consumables Tracker'!$D:$D,$A19,'SAMA Consumables Tracker'!$F:$F) -> 0 | F19: =D19-E19 -> 6750 | G19: =IFERROR(E19/D19,0) -> 0
A20: 5101160010 | B20: Software Licensing & Maintenance | D20: =SUMIF('ACAH Capital Tracker'!$D:$D,$A20,'ACAH Capital Tracker'!$E:$E)+SUMIF('ACAH Consumables Tracker'!$D:$D,$A20,'ACAH Consumables Tracker'!$E:$E)+SUMIF('ACAS Capital Tracker'!$D:$D,$A20,'ACAS Capital Tracker'!$E:$E)+SUMIF('ACAS Consumables Tracker'!$D:$D,$A20,'ACAS Consumables Tracker'!$E:$E)+SUMIF('SAMA Capital Tracker'!$D:$D,$A20,'SAMA Capital Tracker'!$E:$E)+SUMIF('SAMA Consumables Tracker'!$D:$D,$A20,'SAMA Consumables Tracker'!$E:$E) -> 65750 | E20: =SUMIF('ACAH Capital Tracker'!$D:$D,$A20,'ACAH Capital Tracker'!$F:$F)+SUMIF('ACAH Consumables Tracker'!$D:$D,$A20,'ACAH Consumables Tracker'!$F:$F)+SUMIF('ACAS Capital Tracker'!$D:$D,$A20,'ACAS Capital Tracker'!$F:$F)+SUMIF('ACAS Consumables Tracker'!$D:$D,$A20,'ACAS Consumables Tracker'!$F:$F)+SUMIF('SAMA Capital Tracker'!$D:$D,$A20,'SAMA Capital Tracker'!$F:$F)+SUMIF('SAMA Consumables Tracker'!$D:$D,$A20,'SAMA Consumables Tracker'!$F:$F) -> 361.212 | F20: =D20-E20 -> 65388.788 | G20: =IFERROR(E20/D20,0) -> 0.0054937186
A21: 5101170001 | B21: Subscriptions / Educational Software | D21: =SUMIF('ACAH Capital Tracker'!$D:$D,$A21,'ACAH Capital Tracker'!$E:$E)+SUMIF('ACAH Consumables Tracker'!$D:$D,$A21,'ACAH Consumables Tracker'!$E:$E)+SUMIF('ACAS Capital Tracker'!$D:$D,$A21,'ACAS Capital Tracker'!$E:$E)+SUMIF('ACAS Consumables Tracker'!$D:$D,$A21,'ACAS Consumables Tracker'!$E:$E)+SUMIF('SAMA Capital Tracker'!$D:$D,$A21,'SAMA Capital Tracker'!$E:$E)+SUMIF('SAMA Consumables Tracker'!$D:$D,$A21,'SAMA Consumables Tracker'!$E:$E) -> 138650 | E21: =SUMIF('ACAH Capital Tracker'!$D:$D,$A21,'ACAH Capital Tracker'!$F:$F)+SUMIF('ACAH Consumables Tracker'!$D:$D,$A21,'ACAH Consumables Tracker'!$F:$F)+SUMIF('ACAS Capital Tracker'!$D:$D,$A21,'ACAS Capital Tracker'!$F:$F)+SUMIF('ACAS Consumables Tracker'!$D:$D,$A21,'ACAS Consumables Tracker'!$F:$F)+SUMIF('SAMA Capital Tracker'!$D:$D,$A21,'SAMA Capital Tracker'!$F:$F)+SUMIF('SAMA Consumables Tracker'!$D:$D,$A21,'SAMA Consumables Tracker'!$F:$F) -> 541.818 | F21: =D21-E21 -> 138108.18 | G21: =IFERROR(E21/D21,0) -> 0.003907811
A22: 5101200002 | B22: Internet & ISDN Subscriptions | D22: =SUMIF('ACAH Capital Tracker'!$D:$D,$A22,'ACAH Capital Tracker'!$E:$E)+SUMIF('ACAH Consumables Tracker'!$D:$D,$A22,'ACAH Consumables Tracker'!$E:$E)+SUMIF('ACAS Capital Tracker'!$D:$D,$A22,'ACAS Capital Tracker'!$E:$E)+SUMIF('ACAS Consumables Tracker'!$D:$D,$A22,'ACAS Consumables Tracker'!$E:$E)+SUMIF('SAMA Capital Tracker'!$D:$D,$A22,'SAMA Capital Tracker'!$E:$E)+SUMIF('SAMA Consumables Tracker'!$D:$D,$A22,'SAMA Consumables Tracker'!$E:$E) -> 92550 | E22: =SUMIF('ACAH Capital Tracker'!$D:$D,$A22,'ACAH Capital Tracker'!$F:$F)+SUMIF('ACAH Consumables Tracker'!$D:$D,$A22,'ACAH Consumables Tracker'!$F:$F)+SUMIF('ACAS Capital Tracker'!$D:$D,$A22,'ACAS Capital Tracker'!$F:$F)+SUMIF('ACAS Consumables Tracker'!$D:$D,$A22,'ACAS Consumables Tracker'!$F:$F)+SUMIF('SAMA Capital Tracker'!$D:$D,$A22,'SAMA Capital Tracker'!$F:$F)+SUMIF('SAMA Consumables Tracker'!$D:$D,$A22,'SAMA Consumables Tracker'!$F:$F) -> 8235 | F22: =D22-E22 -> 84315 | G22: =IFERROR(E22/D22,0) -> 0.08897893
A23: 5202010022 | B23: IT Training & PD - Admin (SAMA) | D23: =SUMIF('ACAH Capital Tracker'!$D:$D,$A23,'ACAH Capital Tracker'!$E:$E)+SUMIF('ACAH Consumables Tracker'!$D:$D,$A23,'ACAH Consumables Tracker'!$E:$E)+SUMIF('ACAS Capital Tracker'!$D:$D,$A23,'ACAS Capital Tracker'!$E:$E)+SUMIF('ACAS Consumables Tracker'!$D:$D,$A23,'ACAS Consumables Tracker'!$E:$E)+SUMIF('SAMA Capital Tracker'!$D:$D,$A23,'SAMA Capital Tracker'!$E:$E)+SUMIF('SAMA Consumables Tracker'!$D:$D,$A23,'SAMA Consumables Tracker'!$E:$E) -> 3000 | E23: =SUMIF('ACAH Capital Tracker'!$D:$D,$A23,'ACAH Capital Tracker'!$F:$F)+SUMIF('ACAH Consumables Tracker'!$D:$D,$A23,'ACAH Consumables Tracker'!$F:$F)+SUMIF('ACAS Capital Tracker'!$D:$D,$A23,'ACAS Capital Tracker'!$F:$F)+SUMIF('ACAS Consumables Tracker'!$D:$D,$A23,'ACAS Consumables Tracker'!$F:$F)+SUMIF('SAMA Capital Tracker'!$D:$D,$A23,'SAMA Capital Tracker'!$F:$F)+SUMIF('SAMA Consumables Tracker'!$D:$D,$A23,'SAMA Consumables Tracker'!$F:$F) -> 0 | F23: =D23-E23 -> 3000 | G23: =IFERROR(E23/D23,0) -> 0
A24: 5202180001 | B24: Software Licenses - Admin (SAMA) | D24: =SUMIF('ACAH Capital Tracker'!$D:$D,$A24,'ACAH Capital Tracker'!$E:$E)+SUMIF('ACAH Consumables Tracker'!$D:$D,$A24,'ACAH Consumables Tracker'!$E:$E)+SUMIF('ACAS Capital Tracker'!$D:$D,$A24,'ACAS Capital Tracker'!$E:$E)+SUMIF('ACAS Consumables Tracker'!$D:$D,$A24,'ACAS Consumables Tracker'!$E:$E)+SUMIF('SAMA Capital Tracker'!$D:$D,$A24,'SAMA Capital Tracker'!$E:$E)+SUMIF('SAMA Consumables Tracker'!$D:$D,$A24,'SAMA Consumables Tracker'!$E:$E) -> 35000 | E24: =SUMIF('ACAH Capital Tracker'!$D:$D,$A24,'ACAH Capital Tracker'!$F:$F)+SUMIF('ACAH Consumables Tracker'!$D:$D,$A24,'ACAH Consumables Tracker'!$F:$F)+SUMIF('ACAS Capital Tracker'!$D:$D,$A24,'ACAS Capital Tracker'!$F:$F)+SUMIF('ACAS Consumables Tracker'!$D:$D,$A24,'ACAS Consumables Tracker'!$F:$F)+SUMIF('SAMA Capital Tracker'!$D:$D,$A24,'SAMA Capital Tracker'!$F:$F)+SUMIF('SAMA Consumables Tracker'!$D:$D,$A24,'SAMA Consumables Tracker'!$F:$F) -> 750 | F24: =D24-E24 -> 34250 | G24: =IFERROR(E24/D24,0) -> 0.021428571
A25: 5202190005 | B25: Domain Name Registration - Admin (SAMA) | D25: =SUMIF('ACAH Capital Tracker'!$D:$D,$A25,'ACAH Capital Tracker'!$E:$E)+SUMIF('ACAH Consumables Tracker'!$D:$D,$A25,'ACAH Consumables Tracker'!$E:$E)+SUMIF('ACAS Capital Tracker'!$D:$D,$A25,'ACAS Capital Tracker'!$E:$E)+SUMIF('ACAS Consumables Tracker'!$D:$D,$A25,'ACAS Consumables Tracker'!$E:$E)+SUMIF('SAMA Capital Tracker'!$D:$D,$A25,'SAMA Capital Tracker'!$E:$E)+SUMIF('SAMA Consumables Tracker'!$D:$D,$A25,'SAMA Consumables Tracker'!$E:$E) -> 250 | E25: =SUMIF('ACAH Capital Tracker'!$D:$D,$A25,'ACAH Capital Tracker'!$F:$F)+SUMIF('ACAH Consumables Tracker'!$D:$D,$A25,'ACAH Consumables Tracker'!$F:$F)+SUMIF('ACAS Capital Tracker'!$D:$D,$A25,'ACAS Capital Tracker'!$F:$F)+SUMIF('ACAS Consumables Tracker'!$D:$D,$A25,'ACAS Consumables Tracker'!$F:$F)+SUMIF('SAMA Capital Tracker'!$D:$D,$A25,'SAMA Capital Tracker'!$F:$F)+SUMIF('SAMA Consumables Tracker'!$D:$D,$A25,'SAMA Consumables Tracker'!$F:$F) -> 0 | F25: =D25-E25 -> 250 | G25: =IFERROR(E25/D25,0) -> 0
A26: 5202200001 | B26: Internet & Communication - Admin (SAMA) | D26: =SUMIF('ACAH Capital Tracker'!$D:$D,$A26,'ACAH Capital Tracker'!$E:$E)+SUMIF('ACAH Consumables Tracker'!$D:$D,$A26,'ACAH Consumables Tracker'!$E:$E)+SUMIF('ACAS Capital Tracker'!$D:$D,$A26,'ACAS Capital Tracker'!$E:$E)+SUMIF('ACAS Consumables Tracker'!$D:$D,$A26,'ACAS Consumables Tracker'!$E:$E)+SUMIF('SAMA Capital Tracker'!$D:$D,$A26,'SAMA Capital Tracker'!$E:$E)+SUMIF('SAMA Consumables Tracker'!$D:$D,$A26,'SAMA Consumables Tracker'!$E:$E) -> 7150 | E26: =SUMIF('ACAH Capital Tracker'!$D:$D,$A26,'ACAH Capital Tracker'!$F:$F)+SUMIF('ACAH Consumables Tracker'!$D:$D,$A26,'ACAH Consumables Tracker'!$F:$F)+SUMIF('ACAS Capital Tracker'!$D:$D,$A26,'ACAS Capital Tracker'!$F:$F)+SUMIF('ACAS Consumables Tracker'!$D:$D,$A26,'ACAS Consumables Tracker'!$F:$F)+SUMIF('SAMA Capital Tracker'!$D:$D,$A26,'SAMA Capital Tracker'!$F:$F)+SUMIF('SAMA Consumables Tracker'!$D:$D,$A26,'SAMA Consumables Tracker'!$F:$F) -> 0 | F26: =D26-E26 -> 7150 | G26: =IFERROR(E26/D26,0) -> 0
A27: 5202200005 | B27: Website Support - Admin (SAMA) | D27: =SUMIF('ACAH Capital Tracker'!$D:$D,$A27,'ACAH Capital Tracker'!$E:$E)+SUMIF('ACAH Consumables Tracker'!$D:$D,$A27,'ACAH Consumables Tracker'!$E:$E)+SUMIF('ACAS Capital Tracker'!$D:$D,$A27,'ACAS Capital Tracker'!$E:$E)+SUMIF('ACAS Consumables Tracker'!$D:$D,$A27,'ACAS Consumables Tracker'!$E:$E)+SUMIF('SAMA Capital Tracker'!$D:$D,$A27,'SAMA Capital Tracker'!$E:$E)+SUMIF('SAMA Consumables Tracker'!$D:$D,$A27,'SAMA Consumables Tracker'!$E:$E) -> 0 | E27: =SUMIF('ACAH Capital Tracker'!$D:$D,$A27,'ACAH Capital Tracker'!$F:$F)+SUMIF('ACAH Consumables Tracker'!$D:$D,$A27,'ACAH Consumables Tracker'!$F:$F)+SUMIF('ACAS Capital Tracker'!$D:$D,$A27,'ACAS Capital Tracker'!$F:$F)+SUMIF('ACAS Consumables Tracker'!$D:$D,$A27,'ACAS Consumables Tracker'!$F:$F)+SUMIF('SAMA Capital Tracker'!$D:$D,$A27,'SAMA Capital Tracker'!$F:$F)+SUMIF('SAMA Consumables Tracker'!$D:$D,$A27,'SAMA Consumables Tracker'!$F:$F) -> 0 | F27: =D27-E27 -> 0 | G27: =IFERROR(E27/D27,0) -> 0
B28: GL CODE GRAND TOTAL | D28: =SUM(D16:D27) -> 514875 | E28: =SUM(E16:E27) -> 9888.03 | F28: =D28-E28 -> 504986.97 | G28: =IFERROR(E28/D28,0) -> 0.01920472
A30: =IF(ROUND(D12-D28,2)=0,"✅ Section 1 total = Section 2 (GL) total = KWD "&TEXT(D12,"#,##0")&" — BALANCED","❌ MISMATCH: "&TEXT(D12,"#,##0")&" vs "&TEXT(D28,"#,##0")) -> ✅ Section 1 total = Section 2 (GL) total = KWD 514,875 — BALANCED

Sheet ACAH Capital Tracker
A1: ACA Hawally — IT Capital Budget Tracker | FY 2026-27 | KWD
A2: ▶ Budget scenario (set on Summary): | C2: ='IT Budget Summary'!$C$2 -> Offline Optimized | E2: Budget = Approved+Adjustments basis | Adjustments (G) transfer between lines | Available = Budget+Adj−Utilized | Utilization bar: green ≤50 / amber 50–75 / red >75
A3: Unique Code | B3: Line | C3: Description | D3: GL Code | E3: Budget 2026-27 (scenario) | F3: Utilized (SUMIF) | G3: Adjustments (Transfer ±) | H3: Available Balance | I3: Utilization
A4: ACAH-CAP-01 | B4: 1 | C4: Laptops - Teachers | D4: 1101010009 | E4: =CHOOSE(MATCH($C$2,{"Offline Optimized","Offline + Online Hybrid","Online Optimized"},0),J4,K4,L4) -> 7500 | F4: =SUMIF('ACAH Capital Log'!$D$4:$D$2000,A4,'ACAH Capital Log'!$F$4:$F$2000) -> 0 | G4: 0 | H4: =E4+G4-F4 -> 7500 | I4: =IFERROR(IF(($E4+$G4)<=0,"",REPT("█",MIN(20,ROUND($F4/($E4+$G4)*20,0)))),"") | J4: 7500 | K4: 0 | L4: 0 | M4: 6400
A5: ACAH-CAP-02 | B5: 2 | C5: Laptops - Admin | D5: 1101010009 | E5: =CHOOSE(MATCH($C$2,{"Offline Optimized","Offline + Online Hybrid","Online Optimized"},0),J5,K5,L5) -> 3000 | F5: =SUMIF('ACAH Capital Log'!$D$4:$D$2000,A5,'ACAH Capital Log'!$F$4:$F$2000) -> 0 | G5: 0 | H5: =E5+G5-F5 -> 3000 | I5: =IFERROR(IF(($E5+$G5)<=0,"",REPT("█",MIN(20,ROUND($F5/($E5+$G5)*20,0)))),"") | J5: 3000 | K5: 0 | L5: 0 | M5: 1000
A6: ACAH-CAP-03 | B6: 3 | C6: Desktops - Admin | D6: 1101010009 | E6: =CHOOSE(MATCH($C$2,{"Offline Optimized","Offline + Online Hybrid","Online Optimized"},0),J6,K6,L6) -> 0 | F6: =SUMIF('ACAH Capital Log'!$D$4:$D$2000,A6,'ACAH Capital Log'!$F$4:$F$2000) -> 0 | G6: 0 | H6: =E6+G6-F6 -> 0 | I6: =IFERROR(IF(($E6+$G6)<=0,"",REPT("█",MIN(20,ROUND($F6/($E6+$G6)*20,0)))),"") | J6: 0 | K6: 0 | L6: 0 | M6: 0
A7: ACAH-CAP-04 | B7: 4 | C7: iPads / Tablets | D7: 1101010009 | E7: =CHOOSE(MATCH($C$2,{"Offline Optimized","Offline + Online Hybrid","Online Optimized"},0),J7,K7,L7) -> 0 | F7: =SUMIF('ACAH Capital Log'!$D$4:$D$2000,A7,'ACAH Capital Log'!$F$4:$F$2000) -> 0 | G7: 0 | H7: =E7+G7-F7 -> 0 | I7: =IFERROR(IF(($E7+$G7)<=0,"",REPT("█",MIN(20,ROUND($F7/($E7+$G7)*20,0)))),"") | J7: 0 | K7: 0 | L7: 0 | M7: 9360
A8: ACAH-CAP-05 | B8: 5 | C8: Interactive Projectors and Laser Projectors | D8: 1101010009 | E8: =CHOOSE(MATCH($C$2,{"Offline Optimized","Offline + Online Hybrid","Online Optimized"},0),J8,K8,L8) -> 0 | F8: =SUMIF('ACAH Capital Log'!$D$4:$D$2000,A8,'ACAH Capital Log'!$F$4:$F$2000) -> 0 | G8: 0 | H8: =E8+G8-F8 -> 0 | I8: =IFERROR(IF(($E8+$G8)<=0,"",REPT("█",MIN(20,ROUND($F8/($E8+$G8)*20,0)))),"") | J8: 0 | K8: 0 | L8: 0 | M8: 0
A9: ACAH-CAP-06 | B9: 6 | C9: Digital Signage | D9: 1101010009 | E9: =CHOOSE(MATCH($C$2,{"Offline Optimized","Offline + Online Hybrid","Online Optimized"},0),J9,K9,L9) -> 0 | F9: =SUMIF('ACAH Capital Log'!$D$4:$D$2000,A9,'ACAH Capital Log'!$F$4:$F$2000) -> 0 | G9: 0 | H9: =E9+G9-F9 -> 0 | I9: =IFERROR(IF(($E9+$G9)<=0,"",REPT("█",MIN(20,ROUND($F9/($E9+$G9)*20,0)))),"") | J9: 0 | K9: 0 | L9: 0 | M9: 0
A10: ACAH-CAP-07 | B10: 7 | C10: MacBook | D10: 1101010009 | E10: =CHOOSE(MATCH($C$2,{"Offline Optimized","Offline + Online Hybrid","Online Optimized"},0),J10,K10,L10) -> 0 | F10: =SUMIF('ACAH Capital Log'!$D$4:$D$2000,A10,'ACAH Capital Log'!$F$4:$F$2000) -> 0 | G10: 0 | H10: =E10+G10-F10 -> 0 | I10: =IFERROR(IF(($E10+$G10)<=0,"",REPT("█",MIN(20,ROUND($F10/($E10+$G10)*20,0)))),"") | J10: 0 | K10: 0 | L10: 0 | M10: 1300
A11: ACAH-CAP-08 | B11: 8 | C11: Carts for iPads / Tablets / Laptops / Virtual Reality | D11: 1101010009 | E11: =CHOOSE(MATCH($C$2,{"Offline Optimized","Offline + Online Hybrid","Online Optimized"},0),J11,K11,L11) -> 0 | F11: =SUMIF('ACAH Capital Log'!$D$4:$D$2000,A11,'ACAH Capital Log'!$F$4:$F$2000) -> 0 | G11: 0 | H11: =E11+G11-F11 -> 0 | I11: =IFERROR(IF(($E11+$G11)<=0,"",REPT("█",MIN(20,ROUND($F11/($E11+$G11)*20,0)))),"") | J11: 0 | K11: 0 | L11: 0 | M11: 0
A12: ACAH-CAP-09 | B12: 9 | C12: Sync Station / Smart Locker | D12: 1101010009 | E12: =CHOOSE(MATCH($C$2,{"Offline Optimized","Offline + Online Hybrid","Online Optimized"},0),J12,K12,L12) -> 0 | F12: =SUMIF('ACAH Capital Log'!$D$4:$D$2000,A12,'ACAH Capital Log'!$F$4:$F$2000) -> 0 | G12: 0 | H12: =E12+G12-F12 -> 0 | I12: =IFERROR(IF(($E12+$G12)<=0,"",REPT("█",MIN(20,ROUND($F12/($E12+$G12)*20,0)))),"") | J12: 0 | K12: 0 | L12: 0 | M12: 0
A13: ACAH-CAP-10 | B13: 10 | C13: Feeder Scanners / Flatbed Scanners | D13: 1101010009 | E13: =CHOOSE(MATCH($C$2,{"Offline Optimized","Offline + Online Hybrid","Online Optimized"},0),J13,K13,L13) -> 0 | F13: =SUMIF('ACAH Capital Log'!$D$4:$D$2000,A13,'ACAH Capital Log'!$F$4:$F$2000) -> 0 | G13: 0 | H13: =E13+G13-F13 -> 0 | I13: =IFERROR(IF(($E13+$G13)<=0,"",REPT("█",MIN(20,ROUND($F13/($E13+$G13)*20,0)))),"") | J13: 0 | K13: 0 | L13: 0 | M13: 0
A14: ACAH-CAP-11 | B14: 11 | C14: Printers / Copiers | D14: 1101010009 | E14: =CHOOSE(MATCH($C$2,{"Offline Optimized","Offline + Online Hybrid","Online Optimized"},0),J14,K14,L14) -> 3500 | F14: =SUMIF('ACAH Capital Log'!$D$4:$D$2000,A14,'ACAH Capital Log'!$F$4:$F$2000) -> 0 | G14: 0 | H14: =E14+G14-F14 -> 3500 | I14: =IFERROR(IF(($E14+$G14)<=0,"",REPT("█",MIN(20,ROUND($F14/($E14+$G14)*20,0)))),"") | J14: 3500 | K14: 0 | L14: 0 | M14: 2500
A15: ACAH-CAP-12 | B15: 12 | C15: Interactive Tables and Touch Screens | D15: 1101010009 | E15: =CHOOSE(MATCH($C$2,{"Offline Optimized","Offline + Online Hybrid","Online Optimized"},0),J15,K15,L15) -> 9100 | F15: =SUMIF('ACAH Capital Log'!$D$4:$D$2000,A15,'ACAH Capital Log'!$F$4:$F$2000) -> 0 | G15: 0 | H15: =E15+G15-F15 -> 9100 | I15: =IFERROR(IF(($E15+$G15)<=0,"",REPT("█",MIN(20,ROUND($F15/($E15+$G15)*20,0)))),"") | J15: 9100 | K15: 0 | L15: 0 | M15: 25800
... A29: ACAH-CAP-26 | B29: 26 | C29: Miscellaneous - Petty Cash | D29: 1101010009 | E29: =CHOOSE(MATCH($C$2,{"Offline Optimized","Offline + Online Hybrid","Online Optimized"},0),J29,K29,L29) -> 0 | F29: =SUMIF('ACAH Capital Log'!$D$4:$D$2000,A29,'ACAH Capital Log'!$F$4:$F$2000) -> 0 | G29: 0 | H29: =E29+G29-F29 -> 0 | I29: =IFERROR(IF(($E29+$G29)<=0,"",REPT("█",MIN(20,ROUND($F29/($E29+$G29)*20,0)))),"") | J29: 0 | K29: 0 | L29: 0 | M29: 0
C30: TOTAL — ACA Hawally IT Capital | E30: =SUM(E4:E29) -> 54150 | F30: =SUM(F4:F29) -> 0 | G30: =SUM(G4:G29) -> 0 | H30: =E30+G30-F30 -> 54150 | I30: =IFERROR(IF(($E30+$G30)<=0,"",REPT("█",MIN(20,ROUND($F30/($E30+$G30)*20,0)))),"") | M30: =SUM(M4:M29) -> 74060

Sheet ACAH Capital Log
A1: ACA Hawally — IT Capital Expense / Commitment Log | FY 2026-27 | KWD | J1: CODES
A2: Pick the Unique Code from the dropdown — Budget Available shows the remaining balance before you enter the amount. Amounts feed the ACAH Capital Tracker automatically. | J2: ACAH-CAP-01
A3: Date | B3: Ref / PRQ No. | C3: Description / Vendor | D3: Unique Code (Dropdown ▼) | E3: Budget Available ★ | F3: Amount (KD) | G3: GL Code (auto) | H3: Remarks | J3: ACAH-CAP-02
E4: =IF($D4="","",IFERROR(VLOOKUP($D4,'ACAH Capital Tracker'!$A:$H,8,FALSE()),"")) | G4: =IF($D4="","",IFERROR(VLOOKUP($D4,'ACAH Capital Tracker'!$A:$D,4,FALSE()),"")) | J4: ACAH-CAP-03
E5: =IF($D5="","",IFERROR(VLOOKUP($D5,'ACAH Capital Tracker'!$A:$H,8,FALSE()),"")) | G5: =IF($D5="","",IFERROR(VLOOKUP($D5,'ACAH Capital Tracker'!$A:$D,4,FALSE()),"")) | J5: ACAH-CAP-04
E6: =IF($D6="","",IFERROR(VLOOKUP($D6,'ACAH Capital Tracker'!$A:$H,8,FALSE()),"")) | G6: =IF($D6="","",IFERROR(VLOOKUP($D6,'ACAH Capital Tracker'!$A:$D,4,FALSE()),"")) | J6: ACAH-CAP-05
E7: =IF($D7="","",IFERROR(VLOOKUP($D7,'ACAH Capital Tracker'!$A:$H,8,FALSE()),"")) | G7: =IF($D7="","",IFERROR(VLOOKUP($D7,'ACAH Capital Tracker'!$A:$D,4,FALSE()),"")) | J7: ACAH-CAP-06
E8: =IF($D8="","",IFERROR(VLOOKUP($D8,'ACAH Capital Tracker'!$A:$H,8,FALSE()),"")) | G8: =IF($D8="","",IFERROR(VLOOKUP($D8,'ACAH Capital Tracker'!$A:$D,4,FALSE()),"")) | J8: ACAH-CAP-07
E9: =IF($D9="","",IFERROR(VLOOKUP($D9,'ACAH Capital Tracker'!$A:$H,8,FALSE()),"")) | G9: =IF($D9="","",IFERROR(VLOOKUP($D9,'ACAH Capital Tracker'!$A:$D,4,FALSE()),"")) | J9: ACAH-CAP-08
E10: =IF($D10="","",IFERROR(VLOOKUP($D10,'ACAH Capital Tracker'!$A:$H,8,FALSE()),"")) | G10: =IF($D10="","",IFERROR(VLOOKUP($D10,'ACAH Capital Tracker'!$A:$D,4,FALSE()),"")) | J10: ACAH-CAP-09
E11: =IF($D11="","",IFERROR(VLOOKUP($D11,'ACAH Capital Tracker'!$A:$H,8,FALSE()),"")) | G11: =IF($D11="","",IFERROR(VLOOKUP($D11,'ACAH Capital Tracker'!$A:$D,4,FALSE()),"")) | J11: ACAH-CAP-10
E12: =IF($D12="","",IFERROR(VLOOKUP($D12,'ACAH Capital Tracker'!$A:$H,8,FALSE()),"")) | G12: =IF($D12="","",IFERROR(VLOOKUP($D12,'ACAH Capital Tracker'!$A:$D,4,FALSE()),"")) | J12: ACAH-CAP-11
E13: =IF($D13="","",IFERROR(VLOOKUP($D13,'ACAH Capital Tracker'!$A:$H,8,FALSE()),"")) | G13: =IF($D13="","",IFERROR(VLOOKUP($D13,'ACAH Capital Tracker'!$A:$D,4,FALSE()),"")) | J13: ACAH-CAP-12
E14: =IF($D14="","",IFERROR(VLOOKUP($D14,'ACAH Capital Tracker'!$A:$H,8,FALSE()),"")) | G14: =IF($D14="","",IFERROR(VLOOKUP($D14,'ACAH Capital Tracker'!$A:$D,4,FALSE()),"")) | J14: ACAH-CAP-13
E15: =IF($D15="","",IFERROR(VLOOKUP($D15,'ACAH Capital Tracker'!$A:$H,8,FALSE()),"")) | G15: =IF($D15="","",IFERROR(VLOOKUP($D15,'ACAH Capital Tracker'!$A:$D,4,FALSE()),"")) | J15: ACAH-CAP-14
... E27: =IF($D27="","",IFERROR(VLOOKUP($D27,'ACAH Capital Tracker'!$A:$H,8,FALSE()),"")) | G27: =IF($D27="","",IFERROR(VLOOKUP($D27,'ACAH Capital Tracker'!$A:$D,4,FALSE()),"")) | J27: ACAH-CAP-26
E28: =IF($D28="","",IFERROR(VLOOKUP($D28,'ACAH Capital Tracker'!$A:$H,8,FALSE()),"")) | G28: =IF($D28="","",IFERROR(VLOOKUP($D28,'ACAH Capital Tracker'!$A:$D,4,FALSE()),""))
E29: =IF($D29="","",IFERROR(VLOOKUP($D29,'ACAH Capital Tracker'!$A:$H,8,FALSE()),"")) | G29: =IF($D29="","",IFERROR(VLOOKUP($D29,'ACAH Capital Tracker'!$A:$D,4,FALSE()),""))
E30: =IF($D30="","",IFERROR(VLOOKUP($D30,'ACAH Capital Tracker'!$A:$H,8,FALSE()),"")) | G30: =IF($D30="","",IFERROR(VLOOKUP($D30,'ACAH Capital Tracker'!$A:$D,4,FALSE()),""))
E31: =IF($D31="","",IFERROR(VLOOKUP($D31,'ACAH Capital Tracker'!$A:$H,8,FALSE()),"")) | G31: =IF($D31="","",IFERROR(VLOOKUP($D31,'ACAH Capital Tracker'!$A:$D,4,FALSE()),""))
E32: =IF($D32="","",IFERROR(VLOOKUP($D32,'ACAH Capital Tracker'!$A:$H,8,FALSE()),"")) | G32: =IF($D32="","",IFERROR(VLOOKUP($D32,'ACAH Capital Tracker'!$A:$D,4,FALSE()),""))
E33: =IF($D33="","",IFERROR(VLOOKUP($D33,'ACAH Capital Tracker'!$A:$H,8,FALSE()),"")) | G33: =IF($D33="","",IFERROR(VLOOKUP($D33,'ACAH Capital Tracker'!$A:$D,4,FALSE()),""))
E34: =IF($D34="","",IFERROR(VLOOKUP($D34,'ACAH Capital Tracker'!$A:$H,8,FALSE()),"")) | G34: =IF($D34="","",IFERROR(VLOOKUP($D34,'ACAH Capital Tracker'!$A:$D,4,FALSE()),""))
E35: =IF($D35="","",IFERROR(VLOOKUP($D35,'ACAH Capital Tracker'!$A:$H,8,FALSE()),"")) | G35: =IF($D35="","",IFERROR(VLOOKUP($D35,'ACAH Capital Tracker'!$A:$D,4,FALSE()),""))
E36: =IF($D36="","",IFERROR(VLOOKUP($D36,'ACAH Capital Tracker'!$A:$H,8,FALSE()),"")) | G36: =IF($D36="","",IFERROR(VLOOKUP($D36,'ACAH Capital Tracker'!$A:$D,4,FALSE()),""))
E37: =IF($D37="","",IFERROR(VLOOKUP($D37,'ACAH Capital Tracker'!$A:$H,8,FALSE()),"")) | G37: =IF($D37="","",IFERROR(VLOOKUP($D37,'ACAH Capital Tracker'!$A:$D,4,FALSE()),""))
E38: =IF($D38="","",IFERROR(VLOOKUP($D38,'ACAH Capital Tracker'!$A:$H,8,FALSE()),"")) | G38: =IF($D38="","",IFERROR(VLOOKUP($D38,'ACAH Capital Tracker'!$A:$D,4,FALSE()),""))
E39: =IF($D39="","",IFERROR(VLOOKUP($D39,'ACAH Capital Tracker'!$A:$H,8,FALSE()),"")) | G39: =IF($D39="","",IFERROR(VLOOKUP($D39,'ACAH Capital Tracker'!$A:$D,4,FALSE()),""))
... E2000: =IF($D2000="","",IFERROR(VLOOKUP($D2000,'ACAH Capital Tracker'!$A:$H,8,FALSE()),"")) | G2000: =IF($D2000="","",IFERROR(VLOOKUP($D2000,'ACAH Capital Tracker'!$A:$D,4,FALSE()),""))
D2002: TOTAL LOGGED | F2002: =SUM(F4:F2000) -> 0

Sheet ACAH Consumables Tracker
A1: ACA Hawally — IT Consumables Budget Tracker | FY 2026-27 | KWD
A2: ▶ Budget scenario (set on Summary): | C2: ='IT Budget Summary'!$C$2 -> Offline Optimized | E2: Budget = Approved+Adjustments basis | Adjustments (G) transfer between lines | Available = Budget+Adj−Utilized | Utilization bar: green ≤50 / amber 50–75 / red >75
A3: Unique Code | B3: Line | C3: Description | D3: GL Code | E3: Budget 2026-27 (scenario) | F3: Utilized (SUMIF) | G3: Adjustments (Transfer ±) | H3: Available Balance | I3: Utilization
A4: ACAH-CON-01 | B4: 01 | C4: Internet Subscription - KEMS | D4: 5101200002 | E4: =CHOOSE(MATCH($C$2,{"Offline Optimized","Offline + Online Hybrid","Online Optimized"},0),J4,K4,L4) -> 9000 | F4: =SUMIF('ACAH Consumables Log'!$D$4:$D$2000,A4,'ACAH Consumables Log'!$F$4:$F$2000) -> 0 | G4: 0 | H4: =E4+G4-F4 -> 9000 | I4: =IFERROR(IF(($E4+$G4)<=0,"",REPT("█",MIN(20,ROUND($F4/($E4+$G4)*20,0)))),"") | J4: 9000 | K4: 0 | L4: 0 | M4: 9000
A5: ACAH-CON-02 | B5: 02 | C5: ISDN Annual Subscription - KEMS | D5: 5101200002 | E5: =CHOOSE(MATCH($C$2,{"Offline Optimized","Offline + Online Hybrid","Online Optimized"},0),J5,K5,L5) -> 1100 | F5: =SUMIF('ACAH Consumables Log'!$D$4:$D$2000,A5,'ACAH Consumables Log'!$F$4:$F$2000) -> 0 | G5: 0 | H5: =E5+G5-F5 -> 1100 | I5: =IFERROR(IF(($E5+$G5)<=0,"",REPT("█",MIN(20,ROUND($F5/($E5+$G5)*20,0)))),"") | J5: 1100 | K5: 0 | L5: 0 | M5: 480
A6: ACAH-CON-03 | B6: 03 | C6: Data Link - Ministry Purpose (KEMS) | D6: 5101200002 | E6: =CHOOSE(MATCH($C$2,{"Offline Optimized","Offline + Online Hybrid","Online Optimized"},0),J6,K6,L6) -> 200 | F6: =SUMIF('ACAH Consumables Log'!$D$4:$D$2000,A6,'ACAH Consumables Log'!$F$4:$F$2000) -> 0 | G6: 0 | H6: =E6+G6-F6 -> 200 | I6: =IFERROR(IF(($E6+$G6)<=0,"",REPT("█",MIN(20,ROUND($F6/($E6+$G6)*20,0)))),"") | J6: 200 | K6: 0 | L6: 0 | M6: 180
A7: ACAH-CON-04 | B7: 04 | C7: Internet Subscription - Zain | D7: 5101200002 | E7: =CHOOSE(MATCH($C$2,{"Offline Optimized","Offline + Online Hybrid","Online Optimized"},0),J7,K7,L7) -> 14200 | F7: =SUMIF('ACAH Consumables Log'!$D$4:$D$2000,A7,'ACAH Consumables Log'!$F$4:$F$2000) -> 0 | G7: 0 | H7: =E7+G7-F7 -> 14200 | I7: =IFERROR(IF(($E7+$G7)<=0,"",REPT("█",MIN(20,ROUND($F7/($E7+$G7)*20,0)))),"") | J7: 14200 | K7: 0 | L7: 0 | M7: 13200
A8: ACAH-CON-05 | B8: 05 | C8: Internet Subscription - 5G (Principals / Buildings) | D8: 5101200002 | E8: =CHOOSE(MATCH($C$2,{"Offline Optimized","Offline + Online Hybrid","Online Optimized"},0),J8,K8,L8) -> 10000 | F8: =SUMIF('ACAH Consumables Log'!$D$4:$D$2000,A8,'ACAH Consumables Log'!$F$4:$F$2000) -> 0 | G8: 0 | H8: =E8+G8-F8 -> 10000 | I8: =IFERROR(IF(($E8+$G8)<=0,"",REPT("█",MIN(20,ROUND($F8/($E8+$G8)*20,0)))),"") | J8: 10000 | K8: 0 | L8: 0 | M8: 7500
A9: ACAH-CON-06 | B9: 06 | C9: Fiber Rental - MOT | D9: 5101200002 | E9: =CHOOSE(MATCH($C$2,{"Offline Optimized","Offline + Online Hybrid","Online Optimized"},0),J9,K9,L9) -> 510 | F9: =SUMIF('ACAH Consumables Log'!$D$4:$D$2000,A9,'ACAH Consumables Log'!$F$4:$F$2000) -> 0 | G9: 0 | H9: =E9+G9-F9 -> 510 | I9: =IFERROR(IF(($E9+$G9)<=0,"",REPT("█",MIN(20,ROUND($F9/($E9+$G9)*20,0)))),"") | J9: 510 | K9: 0 | L9: 0 | M9: 510
A10: ACAH-CON-07 | B10: 07 | C10: Fiber Rental - Boys to Girls Campus (MOT) | D10: 5101200002 | E10: =CHOOSE(MATCH($C$2,{"Offline Optimized","Offline + Online Hybrid","Online Optimized"},0),J10,K10,L10) -> 900 | F10: =SUMIF('ACAH Consumables Log'!$D$4:$D$2000,A10,'ACAH Consumables Log'!$F$4:$F$2000) -> 0 | G10: 0 | H10: =E10+G10-F10 -> 900 | I10: =IFERROR(IF(($E10+$G10)<=0,"",REPT("█",MIN(20,ROUND($F10/($E10+$G10)*20,0)))),"") | J10: 900 | K10: 0 | L10: 0 | M10: 900
A11: ACAH-CON-08 | B11: 08 | C11: Microsoft Licenses | D11: 5101200002 | E11: =CHOOSE(MATCH($C$2,{"Offline Optimized","Offline + Online Hybrid","Online Optimized"},0),J11,K11,L11) -> 12500 | F11: =SUMIF('ACAH Consumables Log'!$D$4:$D$2000,A11,'ACAH Consumables Log'!$F$4:$F$2000) -> 1235 | G11: 0 | H11: =E11+G11-F11 -> 11265 | I11: =IFERROR(IF(($E11+$G11)<=0,"",REPT("█",MIN(20,ROUND($F11/($E11+$G11)*20,0)))),"") -> ██ | J11: 12500 | K11: 0 | L11: 0 | M11: 11000
A12: ACAH-CON-09 | B12: 09 | C12: Firewall License - Fortigate | D12: 5101160010 | E12: =CHOOSE(MATCH($C$2,{"Offline Optimized","Offline + Online Hybrid","Online Optimized"},0),J12,K12,L12) -> 1100 | F12: =SUMIF('ACAH Consumables Log'!$D$4:$D$2000,A12,'ACAH Consumables Log'!$F$4:$F$2000) -> 0 | G12: 0 | H12: =E12+G12-F12 -> 1100 | I12: =IFERROR(IF(($E12+$G12)<=0,"",REPT("█",MIN(20,ROUND($F12/($E12+$G12)*20,0)))),"") | J12: 1100 | K12: 0 | L12: 0 | M12: 0
A13: ACAH-CON-10 | B13: 10 | C13: Firewall License Sophos XGS4300 (Staff) | D13: 5101160010 | E13: =CHOOSE(MATCH($C$2,{"Offline Optimized","Offline + Online Hybrid","Online Optimized"},0),J13,K13,L13) -> 4000 | F13: =SUMIF('ACAH Consumables Log'!$D$4:$D$2000,A13,'ACAH Consumables Log'!$F$4:$F$2000) -> 0 | G13: 0 | H13: =E13+G13-F13 -> 4000 | I13: =IFERROR(IF(($E13+$G13)<=0,"",REPT("█",MIN(20,ROUND($F13/($E13+$G13)*20,0)))),"") | J13: 4000 | K13: 0 | L13: 0 | M13: 2320
A14: ACAH-CON-11 | B14: 11 | C14: Firewall License Sophos XGS5500 (Students) | D14: 5101160010 | E14: =CHOOSE(MATCH($C$2,{"Offline Optimized","Offline + Online Hybrid","Online Optimized"},0),J14,K14,L14) -> 6000 | F14: =SUMIF('ACAH Consumables Log'!$D$4:$D$2000,A14,'ACAH Consumables Log'!$F$4:$F$2000) -> 0 | G14: 0 | H14: =E14+G14-F14 -> 6000 | I14: =IFERROR(IF(($E14+$G14)<=0,"",REPT("█",MIN(20,ROUND($F14/($E14+$G14)*20,0)))),"") | J14: 6000 | K14: 0 | L14: 0 | M14: 6000
A15: ACAH-CON-12 | B15: 12 | C15: Surveillance Renewal Support and Maintenance | D15: 5101160010 | E15: =CHOOSE(MATCH($C$2,{"Offline Optimized","Offline + Online Hybrid","Online Optimized"},0),J15,K15,L15) -> 4250 | F15: =SUMIF('ACAH Consumables Log'!$D$4:$D$2000,A15,'ACAH Consumables Log'!$F$4:$F$2000) -> 0 | G15: 0 | H15: =E15+G15-F15 -> 4250 | I15: =IFERROR(IF(($E15+$G15)<=0,"",REPT("█",MIN(20,ROUND($F15/($E15+$G15)*20,0)))),"") | J15: 4250 | K15: 0 | L15: 0 | M15: 4250
... A43: ACAH-CON-40 | B43: 40 | C43: Miscellaneous | D43: 5101130003 | E43: =CHOOSE(MATCH($C$2,{"Offline Optimized","Offline + Online Hybrid","Online Optimized"},0),J43,K43,L43) -> 1000 | F43: =SUMIF('ACAH Consumables Log'!$D$4:$D$2000,A43,'ACAH Consumables Log'!$F$4:$F$2000) -> 0 | G43: 0 | H43: =E43+G43-F43 -> 1000 | I43: =IFERROR(IF(($E43+$G43)<=0,"",REPT("█",MIN(20,ROUND($F43/($E43+$G43)*20,0)))),"") | J43: 1000 | K43: 0 | L43: 0 | M43: 1000
C44: TOTAL — ACA Hawally IT Consumables | E44: =SUM(E4:E43) -> 197910 | F44: =SUM(F4:F43) -> 1776.818 | G44: =SUM(G4:G43) -> 0 | H44: =E44+G44-F44 -> 196133.18 | I44: =IFERROR(IF(($E44+$G44)<=0,"",REPT("█",MIN(20,ROUND($F44/($E44+$G44)*20,0)))),"") | M44: =SUM(M4:M43) -> 185940

Sheet ACAH Consumables Log
A1: ACA Hawally — IT Consumables Expense / Commitment Log | FY 2026-27 | KWD | J1: CODES
A2: Pick the Unique Code from the dropdown — Budget Available shows the remaining balance before you enter the amount. Amounts feed the ACAH Consumables Tracker automatically. | J2: ACAH-CON-01
A3: Date | B3: Ref / PRQ No. | C3: Description / Vendor | D3: Unique Code (Dropdown ▼) | E3: Budget Available ★ | F3: Amount (KD) | G3: GL Code (auto) | H3: Remarks | J3: ACAH-CON-02
A4: 46195 | B4: PO | C4: Microsift License | D4: ACAH-CON-08 | E4: =IF($D4="","",IFERROR(VLOOKUP($D4,'ACAH Consumables Tracker'!$A:$H,8,FALSE()),"")) -> 11265 | F4: 1235 | G4: =IF($D4="","",IFERROR(VLOOKUP($D4,'ACAH Consumables Tracker'!$A:$D,4,FALSE()),"")) -> 5101200002 | J4: ACAH-CON-03
A5: 46218 | B5: 7451 | C5: EduPay | D5: ACAH-CON-24 | E5: =IF($D5="","",IFERROR(VLOOKUP($D5,'ACAH Consumables Tracker'!$A:$H,8,FALSE()),"")) -> 1858.182 | F5: =+(2913*0.31)*0.6 -> 541.818 | G5: =IF($D5="","",IFERROR(VLOOKUP($D5,'ACAH Consumables Tracker'!$A:$D,4,FALSE()),"")) -> 5101170001 | J5: ACAH-CON-04
E6: =IF($D6="","",IFERROR(VLOOKUP($D6,'ACAH Consumables Tracker'!$A:$H,8,FALSE()),"")) | G6: =IF($D6="","",IFERROR(VLOOKUP($D6,'ACAH Consumables Tracker'!$A:$D,4,FALSE()),"")) | J6: ACAH-CON-05
E7: =IF($D7="","",IFERROR(VLOOKUP($D7,'ACAH Consumables Tracker'!$A:$H,8,FALSE()),"")) | G7: =IF($D7="","",IFERROR(VLOOKUP($D7,'ACAH Consumables Tracker'!$A:$D,4,FALSE()),"")) | J7: ACAH-CON-06
E8: =IF($D8="","",IFERROR(VLOOKUP($D8,'ACAH Consumables Tracker'!$A:$H,8,FALSE()),"")) | G8: =IF($D8="","",IFERROR(VLOOKUP($D8,'ACAH Consumables Tracker'!$A:$D,4,FALSE()),"")) | J8: ACAH-CON-07
E9: =IF($D9="","",IFERROR(VLOOKUP($D9,'ACAH Consumables Tracker'!$A:$H,8,FALSE()),"")) | G9: =IF($D9="","",IFERROR(VLOOKUP($D9,'ACAH Consumables Tracker'!$A:$D,4,FALSE()),"")) | J9: ACAH-CON-08
E10: =IF($D10="","",IFERROR(VLOOKUP($D10,'ACAH Consumables Tracker'!$A:$H,8,FALSE()),"")) | G10: =IF($D10="","",IFERROR(VLOOKUP($D10,'ACAH Consumables Tracker'!$A:$D,4,FALSE()),"")) | J10: ACAH-CON-09
E11: =IF($D11="","",IFERROR(VLOOKUP($D11,'ACAH Consumables Tracker'!$A:$H,8,FALSE()),"")) | G11: =IF($D11="","",IFERROR(VLOOKUP($D11,'ACAH Consumables Tracker'!$A:$D,4,FALSE()),"")) | J11: ACAH-CON-10
E12: =IF($D12="","",IFERROR(VLOOKUP($D12,'ACAH Consumables Tracker'!$A:$H,8,FALSE()),"")) | G12: =IF($D12="","",IFERROR(VLOOKUP($D12,'ACAH Consumables Tracker'!$A:$D,4,FALSE()),"")) | J12: ACAH-CON-11
E13: =IF($D13="","",IFERROR(VLOOKUP($D13,'ACAH Consumables Tracker'!$A:$H,8,FALSE()),"")) | G13: =IF($D13="","",IFERROR(VLOOKUP($D13,'ACAH Consumables Tracker'!$A:$D,4,FALSE()),"")) | J13: ACAH-CON-12
E14: =IF($D14="","",IFERROR(VLOOKUP($D14,'ACAH Consumables Tracker'!$A:$H,8,FALSE()),"")) | G14: =IF($D14="","",IFERROR(VLOOKUP($D14,'ACAH Consumables Tracker'!$A:$D,4,FALSE()),"")) | J14: ACAH-CON-13
E15: =IF($D15="","",IFERROR(VLOOKUP($D15,'ACAH Consumables Tracker'!$A:$H,8,FALSE()),"")) | G15: =IF($D15="","",IFERROR(VLOOKUP($D15,'ACAH Consumables Tracker'!$A:$D,4,FALSE()),"")) | J15: ACAH-CON-14
E16: =IF($D16="","",IFERROR(VLOOKUP($D16,'ACAH Consumables Tracker'!$A:$H,8,FALSE()),"")) | G16: =IF($D16="","",IFERROR(VLOOKUP($D16,'ACAH Consumables Tracker'!$A:$D,4,FALSE()),"")) | J16: ACAH-CON-15
E17: =IF($D17="","",IFERROR(VLOOKUP($D17,'ACAH Consumables Tracker'!$A:$H,8,FALSE()),"")) | G17: =IF($D17="","",IFERROR(VLOOKUP($D17,'ACAH Consumables Tracker'!$A:$D,4,FALSE()),"")) | J17: ACAH-CON-16
... E41: =IF($D41="","",IFERROR(VLOOKUP($D41,'ACAH Consumables Tracker'!$A:$H,8,FALSE()),"")) | G41: =IF($D41="","",IFERROR(VLOOKUP($D41,'ACAH Consumables Tracker'!$A:$D,4,FALSE()),"")) | J41: ACAH-CON-40
E42: =IF($D42="","",IFERROR(VLOOKUP($D42,'ACAH Consumables Tracker'!$A:$H,8,FALSE()),"")) | G42: =IF($D42="","",IFERROR(VLOOKUP($D42,'ACAH Consumables Tracker'!$A:$D,4,FALSE()),""))
E43: =IF($D43="","",IFERROR(VLOOKUP($D43,'ACAH Consumables Tracker'!$A:$H,8,FALSE()),"")) | G43: =IF($D43="","",IFERROR(VLOOKUP($D43,'ACAH Consumables Tracker'!$A:$D,4,FALSE()),""))
E44: =IF($D44="","",IFERROR(VLOOKUP($D44,'ACAH Consumables Tracker'!$A:$H,8,FALSE()),"")) | G44: =IF($D44="","",IFERROR(VLOOKUP($D44,'ACAH Consumables Tracker'!$A:$D,4,FALSE()),""))
E45: =IF($D45="","",IFERROR(VLOOKUP($D45,'ACAH Consumables Tracker'!$A:$H,8,FALSE()),"")) | G45: =IF($D45="","",IFERROR(VLOOKUP($D45,'ACAH Consumables Tracker'!$A:$D,4,FALSE()),""))
E46: =IF($D46="","",IFERROR(VLOOKUP($D46,'ACAH Consumables Tracker'!$A:$H,8,FALSE()),"")) | G46: =IF($D46="","",IFERROR(VLOOKUP($D46,'ACAH Consumables Tracker'!$A:$D,4,FALSE()),""))
E47: =IF($D47="","",IFERROR(VLOOKUP($D47,'ACAH Consumables Tracker'!$A:$H,8,FALSE()),"")) | G47: =IF($D47="","",IFERROR(VLOOKUP($D47,'ACAH Consumables Tracker'!$A:$D,4,FALSE()),""))
E48: =IF($D48="","",IFERROR(VLOOKUP($D48,'ACAH Consumables Tracker'!$A:$H,8,FALSE()),"")) | G48: =IF($D48="","",IFERROR(VLOOKUP($D48,'ACAH Consumables Tracker'!$A:$D,4,FALSE()),""))
E49: =IF($D49="","",IFERROR(VLOOKUP($D49,'ACAH Consumables Tracker'!$A:$H,8,FALSE()),"")) | G49: =IF($D49="","",IFERROR(VLOOKUP($D49,'ACAH Consumables Tracker'!$A:$D,4,FALSE()),""))
E50: =IF($D50="","",IFERROR(VLOOKUP($D50,'ACAH Consumables Tracker'!$A:$H,8,FALSE()),"")) | G50: =IF($D50="","",IFERROR(VLOOKUP($D50,'ACAH Consumables Tracker'!$A:$D,4,FALSE()),""))
E51: =IF($D51="","",IFERROR(VLOOKUP($D51,'ACAH Consumables Tracker'!$A:$H,8,FALSE()),"")) | G51: =IF($D51="","",IFERROR(VLOOKUP($D51,'ACAH Consumables Tracker'!$A:$D,4,FALSE()),""))
E52: =IF($D52="","",IFERROR(VLOOKUP($D52,'ACAH Consumables Tracker'!$A:$H,8,FALSE()),"")) | G52: =IF($D52="","",IFERROR(VLOOKUP($D52,'ACAH Consumables Tracker'!$A:$D,4,FALSE()),""))
E53: =IF($D53="","",IFERROR(VLOOKUP($D53,'ACAH Consumables Tracker'!$A:$H,8,FALSE()),"")) | G53: =IF($D53="","",IFERROR(VLOOKUP($D53,'ACAH Consumables Tracker'!$A:$D,4,FALSE()),""))
... E2000: =IF($D2000="","",IFERROR(VLOOKUP($D2000,'ACAH Consumables Tracker'!$A:$H,8,FALSE()),"")) | G2000: =IF($D2000="","",IFERROR(VLOOKUP($D2000,'ACAH Consumables Tracker'!$A:$D,4,FALSE()),""))
D2002: TOTAL LOGGED | F2002: =SUM(F4:F2000) -> 1776.818

Sheet ACAS Capital Tracker
A1: ACA Salmiya — IT Capital Budget Tracker | FY 2026-27 | KWD
A2: ▶ Budget scenario (set on Summary): | C2: ='IT Budget Summary'!$C$2 -> Offline Optimized | E2: Budget = Approved+Adjustments basis | Adjustments (G) transfer between lines | Available = Budget+Adj−Utilized | Utilization bar: green ≤50 / amber 50–75 / red >75
A3: Unique Code | B3: Line | C3: Description | D3: GL Code | E3: Budget 2026-27 (scenario) | F3: Utilized (SUMIF) | G3: Adjustments (Transfer ±) | H3: Available Balance | I3: Utilization
A4: ACAS-CAP-01 | B4: 1 | C4: Laptop - Teachers | D4: 1101010009 | E4: =CHOOSE(MATCH($C$2,{"Offline Optimized","Offline + Online Hybrid","Online Optimized"},0),J4,K4,L4) -> 5625 | F4: =SUMIF('ACAS Capital Log'!$D$4:$D$2000,A4,'ACAS Capital Log'!$F$4:$F$2000) -> 0 | G4: 0 | H4: =E4+G4-F4 -> 5625 | I4: =IFERROR(IF(($E4+$G4)<=0,"",REPT("█",MIN(20,ROUND($F4/($E4+$G4)*20,0)))),"") | J4: 5625 | K4: 0 | L4: 0 | M4: 6400
A5: ACAS-CAP-02 | B5: 2 | C5: Laptops - Admin | D5: 1101010009 | E5: =CHOOSE(MATCH($C$2,{"Offline Optimized","Offline + Online Hybrid","Online Optimized"},0),J5,K5,L5) -> 0 | F5: =SUMIF('ACAS Capital Log'!$D$4:$D$2000,A5,'ACAS Capital Log'!$F$4:$F$2000) -> 0 | G5: 0 | H5: =E5+G5-F5 -> 0 | I5: =IFERROR(IF(($E5+$G5)<=0,"",REPT("█",MIN(20,ROUND($F5/($E5+$G5)*20,0)))),"") | J5: 0 | K5: 0 | L5: 0 | M5: 0
A6: ACAS-CAP-03 | B6: 3 | C6: Desktops - Admin | D6: 1101010009 | E6: =CHOOSE(MATCH($C$2,{"Offline Optimized","Offline + Online Hybrid","Online Optimized"},0),J6,K6,L6) -> 0 | F6: =SUMIF('ACAS Capital Log'!$D$4:$D$2000,A6,'ACAS Capital Log'!$F$4:$F$2000) -> 0 | G6: 0 | H6: =E6+G6-F6 -> 0 | I6: =IFERROR(IF(($E6+$G6)<=0,"",REPT("█",MIN(20,ROUND($F6/($E6+$G6)*20,0)))),"") | J6: 0 | K6: 0 | L6: 0 | M6: 0
A7: ACAS-CAP-04 | B7: 4 | C7: iPads / Tablets | D7: 1101010009 | E7: =CHOOSE(MATCH($C$2,{"Offline Optimized","Offline + Online Hybrid","Online Optimized"},0),J7,K7,L7) -> 0 | F7: =SUMIF('ACAS Capital Log'!$D$4:$D$2000,A7,'ACAS Capital Log'!$F$4:$F$2000) -> 0 | G7: 0 | H7: =E7+G7-F7 -> 0 | I7: =IFERROR(IF(($E7+$G7)<=0,"",REPT("█",MIN(20,ROUND($F7/($E7+$G7)*20,0)))),"") | J7: 0 | K7: 0 | L7: 0 | M7: 6240
A8: ACAS-CAP-05 | B8: 5 | C8: Interactive Projectors and Laser Projectors | D8: 1101010009 | E8: =CHOOSE(MATCH($C$2,{"Offline Optimized","Offline + Online Hybrid","Online Optimized"},0),J8,K8,L8) -> 0 | F8: =SUMIF('ACAS Capital Log'!$D$4:$D$2000,A8,'ACAS Capital Log'!$F$4:$F$2000) -> 0 | G8: 0 | H8: =E8+G8-F8 -> 0 | I8: =IFERROR(IF(($E8+$G8)<=0,"",REPT("█",MIN(20,ROUND($F8/($E8+$G8)*20,0)))),"") | J8: 0 | K8: 0 | L8: 0 | M8: 0
A9: ACAS-CAP-06 | B9: 6 | C9: Digital Signage | D9: 1101010009 | E9: =CHOOSE(MATCH($C$2,{"Offline Optimized","Offline + Online Hybrid","Online Optimized"},0),J9,K9,L9) -> 0 | F9: =SUMIF('ACAS Capital Log'!$D$4:$D$2000,A9,'ACAS Capital Log'!$F$4:$F$2000) -> 0 | G9: 0 | H9: =E9+G9-F9 -> 0 | I9: =IFERROR(IF(($E9+$G9)<=0,"",REPT("█",MIN(20,ROUND($F9/($E9+$G9)*20,0)))),"") | J9: 0 | K9: 0 | L9: 0 | M9: 0
A10: ACAS-CAP-07 | B10: 7 | C10: MacBooks | D10: 1101010009 | E10: =CHOOSE(MATCH($C$2,{"Offline Optimized","Offline + Online Hybrid","Online Optimized"},0),J10,K10,L10) -> 0 | F10: =SUMIF('ACAS Capital Log'!$D$4:$D$2000,A10,'ACAS Capital Log'!$F$4:$F$2000) -> 0 | G10: 0 | H10: =E10+G10-F10 -> 0 | I10: =IFERROR(IF(($E10+$G10)<=0,"",REPT("█",MIN(20,ROUND($F10/($E10+$G10)*20,0)))),"") | J10: 0 | K10: 0 | L10: 0 | M10: 650
A11: ACAS-CAP-08 | B11: 8 | C11: Carts for iPads / Tablets / Laptops / Virtual Reality | D11: 1101010009 | E11: =CHOOSE(MATCH($C$2,{"Offline Optimized","Offline + Online Hybrid","Online Optimized"},0),J11,K11,L11) -> 0 | F11: =SUMIF('ACAS Capital Log'!$D$4:$D$2000,A11,'ACAS Capital Log'!$F$4:$F$2000) -> 0 | G11: 0 | H11: =E11+G11-F11 -> 0 | I11: =IFERROR(IF(($E11+$G11)<=0,"",REPT("█",MIN(20,ROUND($F11/($E11+$G11)*20,0)))),"") | J11: 0 | K11: 0 | L11: 0 | M11: 0
A12: ACAS-CAP-09 | B12: 9 | C12: Sync Station / Smart Locker | D12: 1101010009 | E12: =CHOOSE(MATCH($C$2,{"Offline Optimized","Offline + Online Hybrid","Online Optimized"},0),J12,K12,L12) -> 0 | F12: =SUMIF('ACAS Capital Log'!$D$4:$D$2000,A12,'ACAS Capital Log'!$F$4:$F$2000) -> 0 | G12: 0 | H12: =E12+G12-F12 -> 0 | I12: =IFERROR(IF(($E12+$G12)<=0,"",REPT("█",MIN(20,ROUND($F12/($E12+$G12)*20,0)))),"") | J12: 0 | K12: 0 | L12: 0 | M12: 0
A13: ACAS-CAP-10 | B13: 10 | C13: Feeder Scanners / Flatbed Scanners | D13: 1101010009 | E13: =CHOOSE(MATCH($C$2,{"Offline Optimized","Offline + Online Hybrid","Online Optimized"},0),J13,K13,L13) -> 0 | F13: =SUMIF('ACAS Capital Log'!$D$4:$D$2000,A13,'ACAS Capital Log'!$F$4:$F$2000) -> 0 | G13: 0 | H13: =E13+G13-F13 -> 0 | I13: =IFERROR(IF(($E13+$G13)<=0,"",REPT("█",MIN(20,ROUND($F13/($E13+$G13)*20,0)))),"") | J13: 0 | K13: 0 | L13: 0 | M13: 0
A14: ACAS-CAP-11 | B14: 11 | C14: Printers / Copiers | D14: 1101010009 | E14: =CHOOSE(MATCH($C$2,{"Offline Optimized","Offline + Online Hybrid","Online Optimized"},0),J14,K14,L14) -> 2500 | F14: =SUMIF('ACAS Capital Log'!$D$4:$D$2000,A14,'ACAS Capital Log'!$F$4:$F$2000) -> 0 | G14: 0 | H14: =E14+G14-F14 -> 2500 | I14: =IFERROR(IF(($E14+$G14)<=0,"",REPT("█",MIN(20,ROUND($F14/($E14+$G14)*20,0)))),"") | J14: 2500 | K14: 0 | L14: 0 | M14: 2500
A15: ACAS-CAP-12 | B15: 12 | C15: ID Card Printer | D15: 1101010009 | E15: =CHOOSE(MATCH($C$2,{"Offline Optimized","Offline + Online Hybrid","Online Optimized"},0),J15,K15,L15) -> 0 | F15: =SUMIF('ACAS Capital Log'!$D$4:$D$2000,A15,'ACAS Capital Log'!$F$4:$F$2000) -> 0 | G15: 0 | H15: =E15+G15-F15 -> 0 | I15: =IFERROR(IF(($E15+$G15)<=0,"",REPT("█",MIN(20,ROUND($F15/($E15+$G15)*20,0)))),"") | J15: 0 | K15: 0 | L15: 0 | M15: 0
... A32: ACAS-CAP-29 | B32: 29 | C32: Miscellaneous - Emergency | D32: 1101010009 | E32: =CHOOSE(MATCH($C$2,{"Offline Optimized","Offline + Online Hybrid","Online Optimized"},0),J32,K32,L32) -> 0 | F32: =SUMIF('ACAS Capital Log'!$D$4:$D$2000,A32,'ACAS Capital Log'!$F$4:$F$2000) -> 0 | G32: 0 | H32: =E32+G32-F32 -> 0 | I32: =IFERROR(IF(($E32+$G32)<=0,"",REPT("█",MIN(20,ROUND($F32/($E32+$G32)*20,0)))),"") | J32: 0 | K32: 0 | L32: 0 | M32: 0
C33: TOTAL — ACA Salmiya IT Capital | E33: =SUM(E4:E32) -> 55625 | F33: =SUM(F4:F32) -> 0 | G33: =SUM(G4:G32) -> 0 | H33: =E33+G33-F33 -> 55625 | I33: =IFERROR(IF(($E33+$G33)<=0,"",REPT("█",MIN(20,ROUND($F33/($E33+$G33)*20,0)))),"") | M33: =SUM(M4:M32) -> 68190

Sheet ACAS Capital Log
A1: ACA Salmiya — IT Capital Expense / Commitment Log | FY 2026-27 | KWD | J1: CODES
A2: Pick the Unique Code from the dropdown — Budget Available shows the remaining balance before you enter the amount. Amounts feed the ACAS Capital Tracker automatically. | J2: ACAS-CAP-01
A3: Date | B3: Ref / PRQ No. | C3: Description / Vendor | D3: Unique Code (Dropdown ▼) | E3: Budget Available ★ | F3: Amount (KD) | G3: GL Code (auto) | H3: Remarks | J3: ACAS-CAP-02
E4: =IF($D4="","",IFERROR(VLOOKUP($D4,'ACAS Capital Tracker'!$A:$H,8,FALSE()),"")) | G4: =IF($D4="","",IFERROR(VLOOKUP($D4,'ACAS Capital Tracker'!$A:$D,4,FALSE()),"")) | J4: ACAS-CAP-03
E5: =IF($D5="","",IFERROR(VLOOKUP($D5,'ACAS Capital Tracker'!$A:$H,8,FALSE()),"")) | G5: =IF($D5="","",IFERROR(VLOOKUP($D5,'ACAS Capital Tracker'!$A:$D,4,FALSE()),"")) | J5: ACAS-CAP-04
E6: =IF($D6="","",IFERROR(VLOOKUP($D6,'ACAS Capital Tracker'!$A:$H,8,FALSE()),"")) | G6: =IF($D6="","",IFERROR(VLOOKUP($D6,'ACAS Capital Tracker'!$A:$D,4,FALSE()),"")) | J6: ACAS-CAP-05
E7: =IF($D7="","",IFERROR(VLOOKUP($D7,'ACAS Capital Tracker'!$A:$H,8,FALSE()),"")) | G7: =IF($D7="","",IFERROR(VLOOKUP($D7,'ACAS Capital Tracker'!$A:$D,4,FALSE()),"")) | J7: ACAS-CAP-06
E8: =IF($D8="","",IFERROR(VLOOKUP($D8,'ACAS Capital Tracker'!$A:$H,8,FALSE()),"")) | G8: =IF($D8="","",IFERROR(VLOOKUP($D8,'ACAS Capital Tracker'!$A:$D,4,FALSE()),"")) | J8: ACAS-CAP-07
E9: =IF($D9="","",IFERROR(VLOOKUP($D9,'ACAS Capital Tracker'!$A:$H,8,FALSE()),"")) | G9: =IF($D9="","",IFERROR(VLOOKUP($D9,'ACAS Capital Tracker'!$A:$D,4,FALSE()),"")) | J9: ACAS-CAP-08
E10: =IF($D10="","",IFERROR(VLOOKUP($D10,'ACAS Capital Tracker'!$A:$H,8,FALSE()),"")) | G10: =IF($D10="","",IFERROR(VLOOKUP($D10,'ACAS Capital Tracker'!$A:$D,4,FALSE()),"")) | J10: ACAS-CAP-09
E11: =IF($D11="","",IFERROR(VLOOKUP($D11,'ACAS Capital Tracker'!$A:$H,8,FALSE()),"")) | G11: =IF($D11="","",IFERROR(VLOOKUP($D11,'ACAS Capital Tracker'!$A:$D,4,FALSE()),"")) | J11: ACAS-CAP-10
E12: =IF($D12="","",IFERROR(VLOOKUP($D12,'ACAS Capital Tracker'!$A:$H,8,FALSE()),"")) | G12: =IF($D12="","",IFERROR(VLOOKUP($D12,'ACAS Capital Tracker'!$A:$D,4,FALSE()),"")) | J12: ACAS-CAP-11
E13: =IF($D13="","",IFERROR(VLOOKUP($D13,'ACAS Capital Tracker'!$A:$H,8,FALSE()),"")) | G13: =IF($D13="","",IFERROR(VLOOKUP($D13,'ACAS Capital Tracker'!$A:$D,4,FALSE()),"")) | J13: ACAS-CAP-12
E14: =IF($D14="","",IFERROR(VLOOKUP($D14,'ACAS Capital Tracker'!$A:$H,8,FALSE()),"")) | G14: =IF($D14="","",IFERROR(VLOOKUP($D14,'ACAS Capital Tracker'!$A:$D,4,FALSE()),"")) | J14: ACAS-CAP-13
E15: =IF($D15="","",IFERROR(VLOOKUP($D15,'ACAS Capital Tracker'!$A:$H,8,FALSE()),"")) | G15: =IF($D15="","",IFERROR(VLOOKUP($D15,'ACAS Capital Tracker'!$A:$D,4,FALSE()),"")) | J15: ACAS-CAP-14
... E30: =IF($D30="","",IFERROR(VLOOKUP($D30,'ACAS Capital Tracker'!$A:$H,8,FALSE()),"")) | G30: =IF($D30="","",IFERROR(VLOOKUP($D30,'ACAS Capital Tracker'!$A:$D,4,FALSE()),"")) | J30: ACAS-CAP-29
E31: =IF($D31="","",IFERROR(VLOOKUP($D31,'ACAS Capital Tracker'!$A:$H,8,FALSE()),"")) | G31: =IF($D31="","",IFERROR(VLOOKUP($D31,'ACAS Capital Tracker'!$A:$D,4,FALSE()),""))
E32: =IF($D32="","",IFERROR(VLOOKUP($D32,'ACAS Capital Tracker'!$A:$H,8,FALSE()),"")) | G32: =IF($D32="","",IFERROR(VLOOKUP($D32,'ACAS Capital Tracker'!$A:$D,4,FALSE()),""))
E33: =IF($D33="","",IFERROR(VLOOKUP($D33,'ACAS Capital Tracker'!$A:$H,8,FALSE()),"")) | G33: =IF($D33="","",IFERROR(VLOOKUP($D33,'ACAS Capital Tracker'!$A:$D,4,FALSE()),""))
E34: =IF($D34="","",IFERROR(VLOOKUP($D34,'ACAS Capital Tracker'!$A:$H,8,FALSE()),"")) | G34: =IF($D34="","",IFERROR(VLOOKUP($D34,'ACAS Capital Tracker'!$A:$D,4,FALSE()),""))
E35: =IF($D35="","",IFERROR(VLOOKUP($D35,'ACAS Capital Tracker'!$A:$H,8,FALSE()),"")) | G35: =IF($D35="","",IFERROR(VLOOKUP($D35,'ACAS Capital Tracker'!$A:$D,4,FALSE()),""))
E36: =IF($D36="","",IFERROR(VLOOKUP($D36,'ACAS Capital Tracker'!$A:$H,8,FALSE()),"")) | G36: =IF($D36="","",IFERROR(VLOOKUP($D36,'ACAS Capital Tracker'!$A:$D,4,FALSE()),""))
E37: =IF($D37="","",IFERROR(VLOOKUP($D37,'ACAS Capital Tracker'!$A:$H,8,FALSE()),"")) | G37: =IF($D37="","",IFERROR(VLOOKUP($D37,'ACAS Capital Tracker'!$A:$D,4,FALSE()),""))
E38: =IF($D38="","",IFERROR(VLOOKUP($D38,'ACAS Capital Tracker'!$A:$H,8,FALSE()),"")) | G38: =IF($D38="","",IFERROR(VLOOKUP($D38,'ACAS Capital Tracker'!$A:$D,4,FALSE()),""))
E39: =IF($D39="","",IFERROR(VLOOKUP($D39,'ACAS Capital Tracker'!$A:$H,8,FALSE()),"")) | G39: =IF($D39="","",IFERROR(VLOOKUP($D39,'ACAS Capital Tracker'!$A:$D,4,FALSE()),""))
E40: =IF($D40="","",IFERROR(VLOOKUP($D40,'ACAS Capital Tracker'!$A:$H,8,FALSE()),"")) | G40: =IF($D40="","",IFERROR(VLOOKUP($D40,'ACAS Capital Tracker'!$A:$D,4,FALSE()),""))
E41: =IF($D41="","",IFERROR(VLOOKUP($D41,'ACAS Capital Tracker'!$A:$H,8,FALSE()),"")) | G41: =IF($D41="","",IFERROR(VLOOKUP($D41,'ACAS Capital Tracker'!$A:$D,4,FALSE()),""))
E42: =IF($D42="","",IFERROR(VLOOKUP($D42,'ACAS Capital Tracker'!$A:$H,8,FALSE()),"")) | G42: =IF($D42="","",IFERROR(VLOOKUP($D42,'ACAS Capital Tracker'!$A:$D,4,FALSE()),""))
... E2000: =IF($D2000="","",IFERROR(VLOOKUP($D2000,'ACAS Capital Tracker'!$A:$H,8,FALSE()),"")) | G2000: =IF($D2000="","",IFERROR(VLOOKUP($D2000,'ACAS Capital Tracker'!$A:$D,4,FALSE()),""))
D2002: TOTAL LOGGED | F2002: =SUM(F4:F2000) -> 0

Sheet ACAS Consumables Tracker
A1: ACA Salmiya — IT Consumables Budget Tracker | FY 2026-27 | KWD
A2: ▶ Budget scenario (set on Summary): | C2: ='IT Budget Summary'!$C$2 -> Offline Optimized | E2: Budget = Approved+Adjustments basis | Adjustments (G) transfer between lines | Available = Budget+Adj−Utilized | Utilization bar: green ≤50 / amber 50–75 / red >75
A3: Unique Code | B3: Line | C3: Description | D3: GL Code | E3: Budget 2026-27 (scenario) | F3: Utilized (SUMIF) | G3: Adjustments (Transfer ±) | H3: Available Balance | I3: Utilization
A4: ACAS-CON-01 | B4: 1 | C4: Internet Subscription - KEMS | D4: 5101200002 | E4: =CHOOSE(MATCH($C$2,{"Offline Optimized","Offline + Online Hybrid","Online Optimized"},0),J4,K4,L4) -> 6000 | F4: =SUMIF('ACAS Consumables Log'!$D$4:$D$2000,A4,'ACAS Consumables Log'!$F$4:$F$2000) -> 0 | G4: 0 | H4: =E4+G4-F4 -> 6000 | I4: =IFERROR(IF(($E4+$G4)<=0,"",REPT("█",MIN(20,ROUND($F4/($E4+$G4)*20,0)))),"") | J4: 6000 | K4: 0 | L4: 0 | M4: 6000
A5: ACAS-CON-02 | B5: 2 | C5: ISDN Annual Subscription - KEMS | D5: 5101200002 | E5: =CHOOSE(MATCH($C$2,{"Offline Optimized","Offline + Online Hybrid","Online Optimized"},0),J5,K5,L5) -> 480 | F5: =SUMIF('ACAS Consumables Log'!$D$4:$D$2000,A5,'ACAS Consumables Log'!$F$4:$F$2000) -> 0 | G5: 0 | H5: =E5+G5-F5 -> 480 | I5: =IFERROR(IF(($E5+$G5)<=0,"",REPT("█",MIN(20,ROUND($F5/($E5+$G5)*20,0)))),"") | J5: 480 | K5: 0 | L5: 0 | M5: 480
A6: ACAS-CON-03 | B6: 3 | C6: Data Link - Ministry Purpose (KEMS) | D6: 5101200002 | E6: =CHOOSE(MATCH($C$2,{"Offline Optimized","Offline + Online Hybrid","Online Optimized"},0),J6,K6,L6) -> 200 | F6: =SUMIF('ACAS Consumables Log'!$D$4:$D$2000,A6,'ACAS Consumables Log'!$F$4:$F$2000) -> 0 | G6: 0 | H6: =E6+G6-F6 -> 200 | I6: =IFERROR(IF(($E6+$G6)<=0,"",REPT("█",MIN(20,ROUND($F6/($E6+$G6)*20,0)))),"") | J6: 200 | K6: 0 | L6: 0 | M6: 180
A7: ACAS-CON-04 | B7: 4 | C7: Internet Subscription - Zain | D7: 5101200002 | E7: =CHOOSE(MATCH($C$2,{"Offline Optimized","Offline + Online Hybrid","Online Optimized"},0),J7,K7,L7) -> 7800 | F7: =SUMIF('ACAS Consumables Log'!$D$4:$D$2000,A7,'ACAS Consumables Log'!$F$4:$F$2000) -> 0 | G7: 0 | H7: =E7+G7-F7 -> 7800 | I7: =IFERROR(IF(($E7+$G7)<=0,"",REPT("█",MIN(20,ROUND($F7/($E7+$G7)*20,0)))),"") | J7: 7800 | K7: 0 | L7: 0 | M7: 7200
A8: ACAS-CON-05 | B8: 5 | C8: Internet Subscription - 5G | D8: 5101200002 | E8: =CHOOSE(MATCH($C$2,{"Offline Optimized","Offline + Online Hybrid","Online Optimized"},0),J8,K8,L8) -> 7500 | F8: =SUMIF('ACAS Consumables Log'!$D$4:$D$2000,A8,'ACAS Consumables Log'!$F$4:$F$2000) -> 0 | G8: 0 | H8: =E8+G8-F8 -> 7500 | I8: =IFERROR(IF(($E8+$G8)<=0,"",REPT("█",MIN(20,ROUND($F8/($E8+$G8)*20,0)))),"") | J8: 7500 | K8: 0 | L8: 0 | M8: 7500
A9: ACAS-CON-06 | B9: 6 | C9: Fiber Rental - MOT | D9: 5101200002 | E9: =CHOOSE(MATCH($C$2,{"Offline Optimized","Offline + Online Hybrid","Online Optimized"},0),J9,K9,L9) -> 910 | F9: =SUMIF('ACAS Consumables Log'!$D$4:$D$2000,A9,'ACAS Consumables Log'!$F$4:$F$2000) -> 0 | G9: 0 | H9: =E9+G9-F9 -> 910 | I9: =IFERROR(IF(($E9+$G9)<=0,"",REPT("█",MIN(20,ROUND($F9/($E9+$G9)*20,0)))),"") | J9: 910 | K9: 0 | L9: 0 | M9: 910
A10: ACAS-CON-07 | B10: 7 | C10: Microsoft Licenses | D10: 5101200002 | E10: =CHOOSE(MATCH($C$2,{"Offline Optimized","Offline + Online Hybrid","Online Optimized"},0),J10,K10,L10) -> 7000 | F10: =SUMIF('ACAS Consumables Log'!$D$4:$D$2000,A10,'ACAS Consumables Log'!$F$4:$F$2000) -> 7000 | G10: 0 | H10: =E10+G10-F10 -> 0 | I10: =IFERROR(IF(($E10+$G10)<=0,"",REPT("█",MIN(20,ROUND($F10/($E10+$G10)*20,0)))),"") -> ████████████████████ | J10: 7000 | K10: 0 | L10: 0 | M10: 6000
A11: ACAS-CON-08 | B11: 8 | C11: Firewall License Sophos XGS3300 (Staff) | D11: 5101160010 | E11: =CHOOSE(MATCH($C$2,{"Offline Optimized","Offline + Online Hybrid","Online Optimized"},0),J11,K11,L11) -> 3000 | F11: =SUMIF('ACAS Consumables Log'!$D$4:$D$2000,A11,'ACAS Consumables Log'!$F$4:$F$2000) -> 0 | G11: 0 | H11: =E11+G11-F11 -> 3000 | I11: =IFERROR(IF(($E11+$G11)<=0,"",REPT("█",MIN(20,ROUND($F11/($E11+$G11)*20,0)))),"") | J11: 3000 | K11: 0 | L11: 0 | M11: 2300
A12: ACAS-CON-09 | B12: 9 | C12: Firewall License Sophos XGS4300 (Students) | D12: 5101160010 | E12: =CHOOSE(MATCH($C$2,{"Offline Optimized","Offline + Online Hybrid","Online Optimized"},0),J12,K12,L12) -> 3750 | F12: =SUMIF('ACAS Consumables Log'!$D$4:$D$2000,A12,'ACAS Consumables Log'!$F$4:$F$2000) -> 0 | G12: 0 | H12: =E12+G12-F12 -> 3750 | I12: =IFERROR(IF(($E12+$G12)<=0,"",REPT("█",MIN(20,ROUND($F12/($E12+$G12)*20,0)))),"") | J12: 3750 | K12: 0 | L12: 0 | M12: 3750
A13: ACAS-CON-10 | B13: 10 | C13: Surveillance Renewal Support and Maintenance | D13: 5101160010 | E13: =CHOOSE(MATCH($C$2,{"Offline Optimized","Offline + Online Hybrid","Online Optimized"},0),J13,K13,L13) -> 3000 | F13: =SUMIF('ACAS Consumables Log'!$D$4:$D$2000,A13,'ACAS Consumables Log'!$F$4:$F$2000) -> 0 | G13: 0 | H13: =E13+G13-F13 -> 3000 | I13: =IFERROR(IF(($E13+$G13)<=0,"",REPT("█",MIN(20,ROUND($F13/($E13+$G13)*20,0)))),"") | J13: 3000 | K13: 0 | L13: 0 | M13: 3000
A14: ACAS-CON-11 | B14: 11 | C14: Antivirus and Email Protection | D14: 5101200002 | E14: =CHOOSE(MATCH($C$2,{"Offline Optimized","Offline + Online Hybrid","Online Optimized"},0),J14,K14,L14) -> 5250 | F14: =SUMIF('ACAS Consumables Log'!$D$4:$D$2000,A14,'ACAS Consumables Log'!$F$4:$F$2000) -> 0 | G14: 0 | H14: =E14+G14-F14 -> 5250 | I14: =IFERROR(IF(($E14+$G14)<=0,"",REPT("█",MIN(20,ROUND($F14/($E14+$G14)*20,0)))),"") | J14: 5250 | K14: 0 | L14: 0 | M14: 4500
A15: ACAS-CON-12 | B15: 12 | C15: Carts Support and Maintenance | D15: 5101160003 | E15: =CHOOSE(MATCH($C$2,{"Offline Optimized","Offline + Online Hybrid","Online Optimized"},0),J15,K15,L15) -> 0 | F15: =SUMIF('ACAS Consumables Log'!$D$4:$D$2000,A15,'ACAS Consumables Log'!$F$4:$F$2000) -> 0 | G15: 0 | H15: =E15+G15-F15 -> 0 | I15: =IFERROR(IF(($E15+$G15)<=0,"",REPT("█",MIN(20,ROUND($F15/($E15+$G15)*20,0)))),"") | J15: 0 | K15: 0 | L15: 0 | M15: 0
... A41: ACAS-CON-38 | B41: 38 | C41: Miscellaneous | D41: 5101130003 | E41: =CHOOSE(MATCH($C$2,{"Offline Optimized","Offline + Online Hybrid","Online Optimized"},0),J41,K41,L41) -> 0 | F41: =SUMIF('ACAS Consumables Log'!$D$4:$D$2000,A41,'ACAS Consumables Log'!$F$4:$F$2000) -> 0 | G41: 0 | H41: =E41+G41-F41 -> 0 | I41: =IFERROR(IF(($E41+$G41)<=0,"",REPT("█",MIN(20,ROUND($F41/($E41+$G41)*20,0)))),"") | J41: 0 | K41: 0 | L41: 0 | M41: 0
C42: TOTAL — ACA Salmiya IT Consumables | E42: =SUM(E4:E41) -> 146540 | F42: =SUM(F4:F41) -> 7361.212 | G42: =SUM(G4:G41) -> 0 | H42: =E42+G42-F42 -> 139178.79 | I42: =IFERROR(IF(($E42+$G42)<=0,"",REPT("█",MIN(20,ROUND($F42/($E42+$G42)*20,0)))),"") -> █ | M42: =SUM(M4:M41) -> 132220

Sheet ACAS Consumables Log
A1: ACA Salmiya — IT Consumables Expense / Commitment Log | FY 2026-27 | KWD | J1: CODES
A2: Pick the Unique Code from the dropdown — Budget Available shows the remaining balance before you enter the amount. Amounts feed the ACAS Consumables Tracker automatically. | J2: ACAS-CON-01
A3: Date | B3: Ref / PRQ No. | C3: Description / Vendor | D3: Unique Code (Dropdown ▼) | E3: Budget Available ★ | F3: Amount (KD) | G3: GL Code (auto) | H3: Remarks | J3: ACAS-CON-02
A4: 46195 | B4: PO | C4: Microsoft Licence renewal | D4: ACAS-CON-07 | E4: =IF($D4="","",IFERROR(VLOOKUP($D4,'ACAS Consumables Tracker'!$A:$H,8,FALSE()),"")) -> 0 | F4: 7000 | G4: =IF($D4="","",IFERROR(VLOOKUP($D4,'ACAS Consumables Tracker'!$A:$D,4,FALSE()),"")) -> 5101200002 | J4: ACAS-CON-03
A5: 46218 | B5: 7451 | C5: EduPay | D5: ACAS-CON-22 | E5: =IF($D5="","",IFERROR(VLOOKUP($D5,'ACAS Consumables Tracker'!$A:$H,8,FALSE()),"")) -> 2038.788 | F5: =+(2913*0.31)*0.4 -> 361.212 | G5: =IF($D5="","",IFERROR(VLOOKUP($D5,'ACAS Consumables Tracker'!$A:$D,4,FALSE()),"")) -> 5101160010 | J5: ACAS-CON-04
E6: =IF($D6="","",IFERROR(VLOOKUP($D6,'ACAS Consumables Tracker'!$A:$H,8,FALSE()),"")) | G6: =IF($D6="","",IFERROR(VLOOKUP($D6,'ACAS Consumables Tracker'!$A:$D,4,FALSE()),"")) | J6: ACAS-CON-05
E7: =IF($D7="","",IFERROR(VLOOKUP($D7,'ACAS Consumables Tracker'!$A:$H,8,FALSE()),"")) | G7: =IF($D7="","",IFERROR(VLOOKUP($D7,'ACAS Consumables Tracker'!$A:$D,4,FALSE()),"")) | J7: ACAS-CON-06
E8: =IF($D8="","",IFERROR(VLOOKUP($D8,'ACAS Consumables Tracker'!$A:$H,8,FALSE()),"")) | G8: =IF($D8="","",IFERROR(VLOOKUP($D8,'ACAS Consumables Tracker'!$A:$D,4,FALSE()),"")) | J8: ACAS-CON-07
E9: =IF($D9="","",IFERROR(VLOOKUP($D9,'ACAS Consumables Tracker'!$A:$H,8,FALSE()),"")) | G9: =IF($D9="","",IFERROR(VLOOKUP($D9,'ACAS Consumables Tracker'!$A:$D,4,FALSE()),"")) | J9: ACAS-CON-08
E10: =IF($D10="","",IFERROR(VLOOKUP($D10,'ACAS Consumables Tracker'!$A:$H,8,FALSE()),"")) | G10: =IF($D10="","",IFERROR(VLOOKUP($D10,'ACAS Consumables Tracker'!$A:$D,4,FALSE()),"")) | J10: ACAS-CON-09
